Workbook

Sheet SOP
A2: STANDAR OPERASIONAL PROSEDUR
A4: JUDUL | B4: SOP Project Workflow One Spirit Asia
A5: DEPARTEMEN | B5: ALL DEPT
A6: NO DOKUMEN | B6: SOP.OSA.08.IX.2025
A7: TANGGAL PEMBUATAN | B7: 45929
A8: TANGGAL PERUBAHAN | D8: Rev:
A10: 1. Tujuan | B10: Menetapkan alur kerja standar project dari tahap inquiry sampai closing agar seluruh proses tercatat, terdokumentasi, dan terkendali dengan baik sehingga meminimalisir kesalahan, meningkatkan efisiensi, serta memastikan kualitas layanan kepada klien.
A11: 2. Ruang Lingkup | B11: SOP ini berlaku untuk seluruh project event yang ditangani One Spirit Asia, mencakup divisi: > Sales & Marketing > Program & Project > Finance & Administration > Production & Technical > Documentation
A12: 3. Definisi | B12: > Inquiry: Permintaan awal atau ketertarikan klien terhadap layanan event. > Workflow: Alur kerja standar yang harus diikuti dari awal hingga akhir project. > Milestone: Tahapan penting yang menjadi penanda progres project.
A13: 4. Pihak Bertanggung Jawab | B13: > Sales & Marketing (SM) → menerima inquiry, input data klien, koordinasi awal. > Project Manager (PM) → memastikan workflow dijalankan sesuai SOP. > Finance & Admin (FA) → mengelola anggaran, invoice, pembayaran. > Program/Creative → membuat konsep & proposal. > Production/Technical → memastikan kebutuhan teknis event. > Documentation → mengelola hasil dokumentasi (foto, video, teaser).
A14: 5. Prosedur Pelaksanaan | B14: A. Inquiry & MOM > Sales menerima inquiry klien melalui kanal resmi (email, WhatsApp, website, referral). > Sales mengisi kolom Inquiry pada Project Workflow (tanggal, nama klien, PIC, kebutuhan awal). > Sales membuat Minutes of Meeting (MOM) jika ada meeting awal, lalu upload ke folder project. B. Customer Detail > Data lengkap klien diisi di kolom Customer Detail (nama project, kategori, CP, email, nomor HP). > Sales wajib memastikan data ini lengkap sebelum masuk tahap program. C. Program Detail > Program/Creative membuat konsep & proposal sesuai kebutuhan klien. > PM mengisi kategori event, program, venue, tanggal mulai & selesai. > Draft proposal dilampirkan di folder project, link dicatat di kolom workflow. D. Progress Detail > Proposal yang sudah jadi dikirim ke klien → status dicatat (Quotation Sent). > Nomor quotation, tanggal, dan status (Pending, Won, Lost) wajib diisi. > Jika deal → upload file kontrak / signed file ke folder project, update status “Signed”. > Jika batal → isi alasan pembatalan. E. Instrument > PM bersama tim checklist kebutuhan teknis (venue, catering, stage, multimedia, dll). > Status kesiapan dicatat di kolom Instrument. F. Payment Detail > Finance mengisi estimasi budget di kolom Budget (Rp). > Finance membuat jadwal pembayaran (DP, termin, pelunasan). > Status invoice dan pembayaran wajib diupdate secara real-time. > Jika ada keterlambatan, Finance follow up & catat di kolom Note. G. Dokumentasi > Tim dokumentasi wajib menyimpan semua hasil dokumentasi di folder drive. > Link foto, video, teaser, dan media sosial (IG/YouTube) dicatat di workflow. H. Closing Project Project dianggap SELESAI jika: > Semua milestone tercapai. > Seluruh pembayaran lunas. > Dokumentasi lengkap & diarsipkan. > Laporan P&L project sudah selesai. *Workflow di-lock oleh PM dan hanya bisa dibuka kembali oleh Finance/Admin jika ada audit.
A15: 6. Kontrol & Evaluasi | B15: > PM wajib melakukan review mingguan atas semua project di workflow. > Laporan bulanan diserahkan ke Managing Director. > Evaluasi project dilakukan 1 minggu setelah event untuk catatan perbaikan.
A16: 7. Konsekuensi Ketidakpatuhan | B16: a. Progress di Luar Workflow > Jika karyawan mengerjakan project tetapi tidak tercantum dalam Project Workflow, maka progress tersebut dianggap sebagai project pribadi, bukan bagian dari project perusahaan dan dianggap menyalahi aturan yang berlaku. > Segala bentuk progress yang tidak tercatat di Project Workflow tidak diakui sebagai tanggung jawab perusahaan. b. Kelengkapan Data Workflow & Insentif > Jika Project Workflow tidak dilengkapi atau tidak diisi sesuai SOP, maka project dianggap belum memenuhi standar administrasi. > Akibatnya, insentif project tidak dapat diklaim atau dicairkan sampai data dinyatakan lengkap.
A17: 8. Keamanan Data & Privasi | B17: a. Kerahasiaan Data > Seluruh data yang tercantum dalam Project Workflow (customer detail, budget, quotation, invoice, dokumentasi, dll.) merupakan aset perusahaan dan bersifat rahasia. > Data hanya boleh diakses dan digunakan untuk kepentingan pekerjaan sesuai dengan SOP. b. Larangan Penyalahgunaan > Dilarang keras mengambil, menyalin, membagikan, atau menggunakan data klien maupun data perusahaan yang tercantum dalam Project Workflow untuk kepentingan pribadi atau pihak luar. > Pelanggaran atas poin ini akan dianggap sebagai tindak penyalahgunaan aset perusahaan dan dapat dikenakan tindakan disiplin sesuai peraturan yang berlaku. c. Akses Terbatas > Akses ke Project Workflow hanya diberikan kepada karyawan sesuai kewenangan dan tanggung jawabnya. > Setiap karyawan wajib menjaga akun, password, serta akses login agar tidak digunakan oleh pihak yang tidak berhak.

Sheet Dashboard
B3: Simple Dashboard
B7: Potential Revenue | F7: Revenue Confirmed | L7: =Helper!J44 -> Quotation Status | P7: =Helper!J11 -> Program Status | T7: =Helper!J23 -> Payment Status | X7: =Helper!M38 -> Customer Category
L8: =Helper!K45 -> 142 | N8: Cancel | P8: =Helper!K12 -> 142 | R8: =Helper!J12 -> Cancel | T8: =Helper!K24 -> 1 | V8: Invoice Sent | X8: =Helper!N40 -> 4 | Z8: =Helper!M40 -> Campus | AB8: =Helper!N43 -> 17 | AD8: =Helper!M43 -> Other
F9: Target 2025 | G9: 9200000000 | H9: =F10/G9*100% -> 1.1492938
B10: =Helper!L71 -> 31515619883 | F10: =Helper!L70 -> 10573503222 | J10: =Helper!E20 -> 0.3355004 | N10: Our Client Cancel | R10: Program Cancel | V10: Invoice in Progress
L12: =IFERROR(__xludf.DUMMYFUNCTION("IFERROR(SPARKLINE(L13,{""charttype"",""bar"";""max"",1;""min"",0;""color1"",""#ef0101""}))"),"") | P12: =IFERROR(__xludf.DUMMYFUNCTION("IFERROR(SPARKLINE(P13,{""charttype"",""bar"";""max"",1;""min"",0;""color1"",""#ef0101""}))"),"") | T12: =IFERROR(__xludf.DUMMYFUNCTION("IFERROR(SPARKLINE(T13,{""charttype"",""bar"";""max"",1;""min"",0;""color1"",""#ffe5ca""}))"),"") | X12: =IFERROR(__xludf.DUMMYFUNCTION("IFERROR(SPARKLINE(X13,{""charttype"",""bar"";""max"",1;""min"",0;""color1"",""#42bdff""}))"),"") | AB12: =IFERROR(__xludf.DUMMYFUNCTION("IFERROR(SPARKLINE(AB13,{""charttype"",""bar"";""max"",1;""min"",0;""color1"",""#42bdff""}))"),"")
L13: =L8/N13 -> 0.53787879 | N13: =B21 -> 264 | P13: =P8/R13 -> 0.53787879 | R13: =B21 -> 264 | T13: =T8/V13 -> 0.0081967213 | V13: =F21 -> 122 | X13: =X8/Z13 -> 0.015151515 | Z13: =B21 -> 264 | AB13: =AB8/AD13 -> 0.064393939 | AD13: =B21 -> 264
L14: 0 | N14: Feedback | P14: =Helper!K13 -> 122 | R14: =Helper!J13 -> Confirm | T14: =Helper!K25 -> 12 | V14: =Helper!J25 -> Out Standing | X14: =Helper!N41 -> 200 | Z14: =Helper!M41 -> Corporate | AB14: =Helper!N44 -> 4 | AD14: =Helper!M44 -> Student
R16: Program Confirm | V16: Payment in progress
F17: 2023 | G17: 2024 | H17: 2025
F18: 7751804687 | G18: 6146278045 | H18: =F10-G18 -> 4427225177 | I18: =F10-F18 -> 2821698535 | L18: =IFERROR(__xludf.DUMMYFUNCTION("IFERROR(SPARKLINE(L19,{""charttype"",""bar"";""max"",1;""min"",0;""color1"",""#ffe5ca""}))"),"") | P18: =IFERROR(__xludf.DUMMYFUNCTION("IFERROR(SPARKLINE(P19,{""charttype"",""bar"";""max"",1;""min"",0;""color1"",""#b6d7a8""}))"),"") | T18: =IFERROR(__xludf.DUMMYFUNCTION("IFERROR(SPARKLINE(T19,{""charttype"",""bar"";""max"",1;""min"",0;""color1"",""#f9cb9c""}))"),"") | X18: =IFERROR(__xludf.DUMMYFUNCTION("IFERROR(SPARKLINE(X19,{""charttype"",""bar"";""max"",1;""min"",0;""color1"",""#ea9999""}))"),"") | AB18: =IFERROR(__xludf.DUMMYFUNCTION("IFERROR(SPARKLINE(AB19,{""charttype"",""bar"";""max"",1;""min"",0;""color1"",""#ea9999""}))"),"")
B19: Total Inquiry | F19: Total Project Deal | J19: =Helper!E21 -> 0.46212121 | L19: =L14/N19 -> 0 | N19: =B21 -> 264 | P19: =P14/R19 -> 0.46212121 | R19: =B21 -> 264 | T19: =T14/V19 -> 0.098360656 | V19: =F21 -> 122 | X19: =X14/Z19 -> 0.75757576 | Z19: =B21 -> 264 | AB19: =AB14/AD19 -> 0.015151515 | AD19: =B21 -> 264
L20: 0 | N20: In Progress | P20: =Helper!K14 -> 264 | R20: Sent | T20: =Helper!K26 -> 103 | V20: =Helper!J26 -> Paid | X20: =Helper!N42 -> 37 | Z20: =Helper!M42 -> Goverment
B21: =Helper!K47 -> 264 | F21: =Helper!K70 -> 122
V22: Project Already Paid
L24: =IFERROR(__xludf.DUMMYFUNCTION("IFERROR(SPARKLINE(L25,{""charttype"",""bar"";""max"",1;""min"",0;""color1"",""#f9cb9c""}))"),"") | P24: =IFERROR(__xludf.DUMMYFUNCTION("IFERROR(SPARKLINE(P25,{""charttype"",""bar"";""max"",1;""min"",0;""color1"",""#f9cb9c""}))"),"") | T24: =IFERROR(__xludf.DUMMYFUNCTION("IFERROR(SPARKLINE(T25,{""charttype"",""bar"";""max"",1;""min"",0;""color1"",""#b6d7a8""}))"),"") | X24: =IFERROR(__xludf.DUMMYFUNCTION("IFERROR(SPARKLINE(X25,{""charttype"",""bar"";""max"",1;""min"",0;""color1"",""#f89f35""}))"),"")
L25: =L20/N25 -> 0 | N25: =B21 -> 264 | P25: =P20/R25 -> 1 | R25: =B21 -> 264 | T25: =T20/V25 -> 0.8442623 | V25: =F21 -> 122 | X25: =X20/Z25 -> 0.14015152 | Z25: =B21 -> 264 | AB25: =IFERROR(__xludf.DUMMYFUNCTION("IFERROR(SPARKLINE(AB26,{""charttype"",""bar"";""max"",1;""min"",0;""color1"",""#f89f35""}))"),"")
B26: Number of Project per Programer | L26: =Helper!K47 -> 264 | N26: Sent | P26: 0 | R26: In Progress
N28: Quotation Sent | R28: Program in Progress
L30: =IFERROR(__xludf.DUMMYFUNCTION("IFERROR(SPARKLINE(L31,{""charttype"",""bar"";""max"",1;""min"",0;""color1"",""#d7f1cc""}))"),"") | P30: =IFERROR(__xludf.DUMMYFUNCTION("IFERROR(SPARKLINE(P31,{""charttype"",""bar"";""max"",1;""min"",0;""color1"",""#ffe5ca""}))"),"")
L31: =L26/N31 -> 1 | N31: =B21 -> 264 | P31: =P26/R31 -> 0 | R31: =B21 -> 264
L32: =Helper!K46 -> 122 | N32: Sign & Deal | P32: 0
N34: Our Client Confirm & Sign | R34: Program have not started
L36: =IFERROR(__xludf.DUMMYFUNCTION("IFERROR(SPARKLINE(L37,{""charttype"",""bar"";""max"",1;""min"",0;""color1"",""#b6d7a8""}))"),"") | P36: =IFERROR(__xludf.DUMMYFUNCTION("IFERROR(SPARKLINE(P37,{""charttype"",""bar"";""max"",1;""min"",0;""color1"",""#ea9999""}))"),"")
L37: =L32/N37 -> 0.46212121 | N37: =B21 -> 264 | P37: =P32/R37 -> 0 | R37: =B21 -> 264
K57: Highest Budget | L57: =Helper!N4 -> 10976511799 | Q57: Tasks vs. Completion Dates
Q60: =Helper!V3 -> P073 | S60: =Helper!T3 -> June-2025
Q62: =Helper!V4 -> P175 | S62: =Helper!T5 -> 46042
L63: =Helper!M3 -> Direct
Q64: =Helper!V5 -> P221 | S64: =Helper!T7 -> 46019
K66: Lowest Budget | L66: =Helper!N8 -> 132043800 | Q66: =Helper!V6 -> P244 | S66: =Helper!T9 -> 46014
Q68: =Helper!V7 -> P247 | S68: =Helper!T11 -> 46009
Q70: =Helper!V8 -> P248 | S70: =Helper!T13 -> 46005
L72: Web | Q72: =Helper!V9 -> P258 | S72: =Helper!T15 -> 46003
Q74: =Helper!V10 -> P253 | S74: =Helper!T17 -> 46000
K75: Average Budget
Q76: =Helper!V11 -> P245 | S76: =Helper!T19 -> 45996
Q78: =Helper!V12 -> P256 | S78: =Helper!T21 -> 45994
Q80: =Helper!V14 -> P249 | S80: =Helper!T23 -> 45992
Q82: =Helper!V16 -> P234 | S82: =Helper!T25 -> 45990
...

Sheet Workflow
B1: Project Workflow One Spirit 2025 | W1: QT0025/JIP/I/2025
B2: INQUERY & MOM | I2: CUSTOMER DETAIL | N2: PROGRAM DETAIL | U2: PROGRESS DETAIL | AB2: INSTRUMENT | AI2: PAYMENT DETAIL | AO2: Dokumentasi
B3: A. Inquiry & MOM -Sales menerima inquiry klien melalui kanal resmi (email, WhatsApp, website, referral). -Sales mengisi kolom Inquiry pada Project Workflow (tanggal, nama klien, PIC, kebutuhan awal). -Sales membuat Minutes of Meeting (MOM) jika ada meeting awal, lalu upload ke folder project. | I3: B. Customer Detail -Data lengkap klien diisi di kolom Customer Detail (nama project, kategori, CP, email, nomor HP). -Sales wajib memastikan data ini lengkap sebelum masuk tahap program. | N3: C. Program Detail -Program/Creative membuat konsep & proposal sesuai kebutuhan klien. -PM mengisi kategori event, program, venue, tanggal mulai & selesai. -Draft proposal dilampirkan di folder project, link dicatat di kolom workflow. | U3: D. Progress Detail -Proposal yang sudah jadi dikirim ke klien → status dicatat (Quotation Sent). -Nomor quotation, tanggal, dan status (Pending, Won, Lost) wajib diisi. -Jika deal → upload file kontrak / signed file ke folder project, update status “Signed”. -Jika batal → isi alasan pembatalan. | AB3: E. Instrument -PM bersama tim checklist kebutuhan teknis (venue, catering, stage, multimedia, dll). -Status kesiapan dicatat di kolom Instrument. | AI3: F. Payment Detail -Finance mengisi estimasi budget di kolom Budget (Rp). -Finance membuat jadwal pembayaran (DP, termin, pelunasan). -Status invoice dan pembayaran wajib diupdate secara real-time. -Jika ada keterlambatan, Finance follow up & catat di kolom Note. | AO3: G. Dokumentasi -Tim dokumentasi wajib menyimpan semua hasil dokumentasi di folder drive. -Link foto, video, teaser, dan media sosial (IG/YouTube) dicatat di workflow.
B5: INQ Date | C5: Section | D5: INQ By | E5: Sales | F5: PO | G5: PM | H5: MoM | I5: Company Name | J5: Customer Category | K5: CP | L5: Phone Number | M5: Email | N5: Event Category | O5: Prog | P5: QTY | Q5: Venue | R5: Dur' | S5: Event Date Start | T5: Event Date End | U5: Milestone | V5: Quotation Date | W5: Quotation Number | X5: Quotation Status | Y5: Program Status | Z5: Signed File | AA5: Cancel Reason | AB5: CL | AC5: ROS | AD5: CK | AE5: PNL | AF5: PF | AG5: Matrix | AH5: Note | AI5: Budget (Rp) | AK5: Payment Schadule | AL5: INVOICE Status | AM5: Payment Status | AN5: Project Status | AO5: Link Photo | AP5: Link Video | AQ5: Link Teaser | AR5: IG | AS5: YT
B6: 45663 | C6: OS | D6: Direct | F6: JIP | G6: OME | I6: Golden Rama Travel JKT | J6: Corporate | N6: Employee Gathering | O6: TB | P6: 7 | Q6: R Hotel Rancamaya | R6: =if(ISBLANK($T6),"",$T6-$S6+1) -> 1 | S6: 45664 | T6: 45664 | U6: =if(W6="","", S6-V6 & " days") -> 1 days | V6: 45663 | W6: P006 | X6: Cancel | Y6: Cancel | AA6: No Response | AB6: TRUE | AC6: FALSE | AD6: FALSE | AE6: TRUE | AF6: FALSE | AG6: FALSE | AI6: 6660000 | AR6: FALSE | AS6: FALSE
B7: 45663 | C7: OS | D7: Direct | F7: JIP | G7: OME | I7: PT Binareka Tatamandiri | J7: Corporate | K7: Mrs. Yenni | L7: +62 813 1915 6490 | N7: Entertainment | O7: ENT | P7: 25 | Q7: Royal Tulip Gunung Geulis | R7: =if(ISBLANK($T7),"",$T7-$S7+1) -> 1 | S7: 45664 | T7: 45664 | U7: =if(W7="","", S7-V7 & " days") -> 1 days | V7: 45663 | W7: P009 | X7: Signed & Deal | Y7: Confirm | AA7: - | AB7: TRUE | AC7: TRUE | AD7: TRUE | AE7: TRUE | AF7: FALSE | AG7: TRUE | AI7: 7500000 | AJ7: =AI7 -> 7500000 | AK7: Paid | AL7: Paid | AM7: Paid | AN7: Closed | AR7: TRUE | AS7: FALSE
B8: 45631 | C8: OS | D8: Hotel | E8: Maria | F8: JIP | G8: OME | I8: PT Binareka Tatamandiri | J8: Corporate | K8: Mrs. Yenni | L8: +62 813 1915 6490 | N8: Employee Gathering | O8: RFT | P8: 25 | Q8: Syifa Adventure Rafting | R8: =if(ISBLANK($T8),"",$T8-$S8+1) -> 1 | S8: 45665 | T8: 45665 | U8: =if(W8="","", S8-V8 & " days") -> 34 days | V8: 45631 | W8: P008 | X8: Signed & Deal | Y8: Confirm | AA8: - | AB8: TRUE | AC8: TRUE | AD8: TRUE | AE8: TRUE | AF8: FALSE | AG8: TRUE | AI8: 12626250 | AJ8: =AI8 -> 12626250 | AK8: Paid | AL8: Paid | AM8: Paid | AN8: Closed | AO8: https://drive.google.com/drive/folders/1-hacH_MoKZTyj9z0iLhVNKVcfEs5SYOv?usp=sharing | AQ8: https://www.instagram.com/onespiritasia/reel/DOz2rL1kodS/ | AR8: TRUE | AS8: FALSE
B9: 45663 | C9: OS | D9: Partner | E9: Linda | F9: JIP | G9: OME | I9: DPRD Banten | J9: Goverment | K9: Mrs. Linda | L9: +62 877-7770-7115 | N9: Employee Gathering | O9: RFT | P9: 15 | Q9: Syifa Adventure Rafting | R9: =if(ISBLANK($T9),"",$T9-$S9+1) -> 1 | S9: 45665 | T9: 45665 | U9: =if(W9="","", S9-V9 & " days") -> 2 days | V9: 45663 | W9: P005 | X9: Signed & Deal | Y9: Confirm | AA9: - | AB9: TRUE | AC9: TRUE | AD9: TRUE | AE9: TRUE | AF9: FALSE | AG9: TRUE | AI9: 4200000 | AJ9: =AI9 -> 4200000 | AK9: Paid | AL9: Paid | AM9: Paid | AN9: Closed | AO9: https://drive.google.com/drive/folders/1fv2kALZPjBrLNY8ilmc52dU_CcVBsGin?usp=sharing | AQ9: https://www.instagram.com/onespiritasia/reel/DEhOFIxyZ1z/ | AR9: TRUE | AS9: FALSE
B10: 45661 | C10: OS | D10: Hotel | E10: Hera | F10: SYS | G10: SYS | I10: Mrs Yani | J10: Other | K10: Mrs. Yani | L10: +62857-1930-3666 | N10: Entertainment | O10: ENT | P10: 50 | Q10: Luminor Hotel Bogor | R10: =if(ISBLANK($T10),"",$T10-$S10+1) -> 1 | S10: 45668 | T10: 45668 | U10: =if(W10="","", S10-V10 & " days") -> 7 days | V10: 45661 | W10: P003 | X10: Cancel | Y10: Cancel | AA10: Budget | AB10: TRUE | AC10: FALSE | AD10: FALSE | AE10: FALSE | AF10: FALSE | AG10: FALSE | AI10: 44500000 | AR10: FALSE | AS10: FALSE
B11: 45667 | C11: OS | D11: Hotel | E11: Nanda | F11: JIP | G11: TF | I11: PGN GAGAS | J11: Goverment | K11: Mrs. Firly | L11: +62 813- 8230-1414 | N11: Employee Gathering | O11: Full Arrangement | P11: 40 | Q11: Alana Sentul | R11: =if(ISBLANK($T11),"",$T11-$S11+1) -> 3 | S11: 45672 | T11: 45674 | U11: =if(W11="","", S11-V11 & " days") -> 5 days | V11: 45667 | W11: P015 | X11: Signed & Deal | Y11: Confirm | AA11: - | AB11: TRUE | AC11: TRUE | AD11: TRUE | AE11: TRUE | AF11: FALSE | AG11: TRUE | AI11: 166349319 | AJ11: =AI11 -> 166349319 | AK11: Paid | AL11: Paid | AM11: Paid | AN11: Closed | AQ11: https://www.instagram.com/onespiritasia/reel/DGKVoHozZvI/ | AR11: TRUE | AS11: FALSE
B12: 45569 | C12: OS | D12: Hotel | E12: Maria | F12: JIP | G12: BR | I12: PT Acer Indonesia | J12: Corporate | K12: Mr. Inyo Kusoy | L12: +62 813-4064-2559 | N12: Employee Gathering | O12: TB - Scavenger Hunt | P12: 140 | Q12: Lap. Leuwi Asih, Hutan Hujan, Royal Tulip | R12: =if(ISBLANK($T12),"",$T12-$S12+1) -> 1 | S12: 45674 | T12: 45674 | U12: =if(W12="","", S12-V12 & " days") -> 105 days | V12: 45569 | W12: P001 | X12: Signed & Deal | Y12: Confirm | AA12: - | AB12: TRUE | AC12: TRUE | AD12: TRUE | AE12: TRUE | AF12: FALSE | AG12: TRUE | AI12: 69406288 | AJ12: 69406288 | AK12: Paid | AL12: Paid | AM12: Paid | AN12: Closed | AO12: https://drive.google.com/drive/folders/1aCJrohtxDWHPEG2Pca8w5ypqgoE7m625?usp=sharing | AQ12: https://www.instagram.com/onespiritasia/reel/DE9k1lQSMNu/ | AR12: TRUE | AS12: FALSE
B13: 45643 | C13: OS | D13: Hotel | E13: Yulia | F13: JIP | G13: TF | I13: PT Energy Unggu Persada | J13: Corporate | K13: Mr. Fortune | N13: Production | O13: Production | Q13: Royal Tulip Gunung Geulis | R13: =if(ISBLANK($T13),"",$T13-$S13+1) -> 2 | S13: 45674 | T13: 45675 | U13: =if(W13="","", S13-V13 & " days") -> 31 days | V13: 45643 | W13: P026 | X13: Signed & Deal | Y13: Confirm | AB13: TRUE | AC13: TRUE | AD13: TRUE | AE13: TRUE | AF13: FALSE | AG13: TRUE | AI13: 79838200 | AJ13: 79838200 | AK13: Paid | AL13: Paid | AM13: Paid | AN13: Closed | AR13: FALSE | AS13: FALSE
B14: 45664 | C14: OS | D14: Hotel | F14: JIP | G14: OME | I14: PT Infinite Business Synergy | J14: Corporate | K14: Mrs. Resha | L14: +62 877-7821-3038 | N14: Employee Gathering | O14: TB | P14: 40 | Q14: Pesona Alam | R14: =if(ISBLANK($T14),"",$T14-$S14+1) -> 1 | S14: 45674 | T14: 45674 | U14: =if(W14="","", S14-V14 & " days") -> 10 days | V14: 45664 | W14: P012 | X14: Cancel | Y14: Cancel | AA14: Internal Reason | AB14: TRUE | AC14: FALSE | AD14: FALSE | AE14: FALSE | AF14: FALSE | AG14: FALSE | AI14: 21645000 | AR14: FALSE | AS14: FALSE
B15: 45665 | C15: LS | D15: Hotel | E15: Roy (Bromelia) | F15: JIP | G15: SB | I15: KB Data System Indonesia | J15: Corporate | K15: Mr. Kimi | L15: +62 878-7323-4949 | N15: Employee Gathering | O15: FG | P15: 42 | Q15: Bromelia | R15: =if(ISBLANK($T15),"",$T15-$S15+1) -> 1 | S15: 45674 | T15: 45674 | U15: =if(W15="","", S15-V15 & " days") -> 9 days | V15: 45665 | W15: P021 | X15: Signed & Deal | Y15: Confirm | AB15: TRUE | AC15: TRUE | AD15: TRUE | AE15: TRUE | AF15: FALSE | AG15: TRUE | AI15: 4620000 | AJ15: =AI15 -> 4620000 | AK15: Paid | AL15: Paid | AM15: Paid | AN15: Closed | AR15: FALSE | AS15: FALSE
B16: 45672 | C16: LS | D16: Hotel | E16: Opik | F16: JIP | G16: OME | I16: PT Mandiri Tunas Finance | J16: Corporate | K16: Mrs. Nabila | L16: +62 812-9669-7498 | N16: Employee Gathering | O16: TB | P16: 26 | Q16: Lenirra Villa & Resto | R16: =if(ISBLANK($T16),"",$T16-$S16+1) -> 1 | S16: 45674 | T16: 45674 | U16: =if(W16="","", S16-V16 & " days") -> 2 days | V16: 45672 | W16: P025 | X16: Signed & Deal | Y16: Confirm | AB16: TRUE | AC16: TRUE | AD16: TRUE | AE16: TRUE | AF16: FALSE | AG16: TRUE | AI16: 2600000 | AJ16: =AI16 -> 2600000 | AK16: Paid | AL16: Paid | AM16: Paid | AN16: Closed | AR16: FALSE | AS16: FALSE
B17: 45672 | C17: LS | D17: Hotel | E17: Opick | F17: JIP | G17: SB | I17: PT Hardana WIdya Mahir | J17: Corporate | K17: Mrs Dinda | L17: +62 895-2343-1883 | N17: Other | O17: OFR | Q17: Lenirra Villa& resto | R17: =if(ISBLANK($T17),"",$T17-$S17+1) -> 2 | S17: 45674 | T17: 45675 | U17: =if(W17="","", S17-V17 & " days") -> 3 days | V17: 45671 | W17: P068 | X17: Signed & Deal | Y17: Confirm | AB17: TRUE | AC17: TRUE | AD17: TRUE | AE17: TRUE | AF17: FALSE | AG17: TRUE | AI17: 3500000 | AJ17: =AI17 -> 3500000 | AK17: Paid | AL17: Paid | AM17: Paid | AN17: Closed | AO17: DOKUMENTASI PT.HARDANA WIDYA MAHIR | AR17: FALSE | AS17: FALSE
B18: 45670 | C18: LS | D18: Hotel | E18: Puji | F18: JIP | G18: SB | I18: Mahakarya Adi Indonesia | J18: Corporate | K18: Mrs. Bella Arifah | L18: +62 817-7679-9928 | N18: Employee Gathering | O18: FG | P18: 65 | Q18: The Botanica Sanctuary | R18: =if(ISBLANK($T18),"",$T18-$S18+1) -> 1 | S18: 45679 | T18: 45679 | U18: =if(W18="","", S18-V18 & " days") -> 9 days | V18: 45670 | W18: P027 | X18: Signed & Deal | Y18: Confirm | AB18: TRUE | AC18: TRUE | AD18: TRUE | AE18: TRUE | AF18: FALSE | AG18: TRUE | AI18: 14300000 | AJ18: =AI18 -> 14300000 | AK18: Paid | AL18: Paid | AM18: Paid | AN18: Closed | AO18: https://drive.google.com/drive/folders/1CtJvNSkqO46UgP2HMHa_LnVbhXdE7RK6?usp=sharing | AR18: FALSE | AS18: FALSE
B19: 45663 | C19: OS | D19: Hotel | F19: JIP | G19: OME | I19: OLX | J19: Corporate | K19: Tannya | L19: +62 896-7218-5308 | N19: Employee Gathering | O19: TB | P19: 132 | Q19: Aston Ciloto | R19: =if(ISBLANK($T19),"",$T19-$S19+1) -> 1 | S19: 45680 | T19: 45680 | U19: =if(W19="","", S19-V19 & " days") -> 17 days | V19: 45663 | W19: P013 | X19: Cancel | Y19: Cancel | AA19: Competitor | AB19: TRUE | AC19: FALSE | AD19: FALSE | AE19: FALSE | AF19: FALSE | AG19: FALSE | AI19: 27838800 | AR19: FALSE | AS19: FALSE
B20: 45668 | C20: OS | D20: Hotel | F20: SYS | G20: SYS | I20: PT Taren Satiu Tuju | J20: Corporate | K20: Mr. Rizqi | L20: 0812-1271-1888 | N20: Production | O20: Production | P20: 250 | Q20: MNC Lido Lake Resort | R20: =if(ISBLANK($T20),"",$T20-$S20+1) -> 2 | S20: 45681 | T20: 45682 | U20: =if(W20="","", S20-V20 & " days") -> 15 days | V20: 45666 | W20: P019 | X20: Cancel | Y20: Cancel | AA20: No Response | AB20: TRUE | AC20: FALSE | AD20: FALSE | AE20: FALSE | AF20: FALSE | AG20: FALSE | AI20: 30834823 | AR20: FALSE | AS20: FALSE
B21: 45671 | C21: LS | D21: Hotel | E21: Opik | F21: JIP | G21: SB | I21: PT Century Distribution System Indonesia | J21: Corporate | K21: Mrs Rahma | L21: +62 856-9495-5900 | N21: Employee Gathering | O21: TB | P21: 35 | Q21: Lenirra Villa & Resto | R21: =if(ISBLANK($T21),"",$T21-$S21+1) -> 1 | S21: 45682 | T21: 45682 | U21: =if(W21="","", S21-V21 & " days") -> 11 days | V21: 45671 | W21: P028 | X21: Signed & Deal | Y21: Confirm | AB21: TRUE | AC21: TRUE | AD21: TRUE | AE21: TRUE | AF21: FALSE | AG21: TRUE | AI21: 3500000 | AJ21: =AI21 -> 3500000 | AK21: Paid | AL21: Paid | AM21: Paid | AN21: Closed | AO21: https://drive.google.com/drive/folders/1mE1BpaeyOE5rUqgy7tk658vqcjWkzj5p?usp=sharing | AQ21: https://www.instagram.com/onespiritasia/reel/DLG6daKyvEd/ | AR21: TRUE | AS21: FALSE
B22: 45671 | C22: LS | D22: Hotel | E22: Opik | F22: JIP | G22: SB | I22: PT Century Distribution System Indonesia | J22: Corporate | K22: Mrs Rahma | L22: +62 856-9495-5901 | N22: Employee Gathering | O22: Others | P22: 35 | Q22: Lenirra Villa & Resto | R22: =if(ISBLANK($T22),"",$T22-$S22+1) -> 2 | S22: 45682 | T22: 45683 | U22: =if(W22="","", S22-V22 & " days") -> 11 days | V22: 45671 | W22: P029 | X22: Signed & Deal | Y22: Confirm | AB22: TRUE | AC22: TRUE | AD22: TRUE | AE22: TRUE | AF22: FALSE | AG22: TRUE | AI22: 4000000 | AJ22: =AI22 -> 4000000 | AK22: Paid | AL22: Paid | AM22: Paid | AN22: Closed | AO22: https://drive.google.com/drive/folders/1mE1BpaeyOE5rUqgy7tk658vqcjWkzj5p?usp=sharing | AQ22: https://www.instagram.com/onespiritasia/reel/DLG6daKyvEd/ | AR22: TRUE | AS22: FALSE
B23: 45672 | C23: OS | D23: Hotel | F23: JIP | G23: TF | I23: APARI | J23: Corporate | K23: Mrs. Lela | L23: 62 823-6200-4881 | N23: Employee Gathering | O23: RFT | P23: 30 | Q23: Alamanda Rafting | R23: =if(ISBLANK($T23),"",$T23-$S23+1) -> 1 | S23: 45689 | T23: 45689 | U23: =if(W23="","", S23-V23 & " days") -> 17 days | V23: 45672 | W23: P023 | X23: Cancel | Y23: Cancel | AA23: No Response | AB23: TRUE | AC23: FALSE | AD23: FALSE | AE23: FALSE | AF23: FALSE | AG23: FALSE | AI23: 19369500 | AR23: FALSE | AS23: FALSE
B24: 45681 | C24: OS | D24: Partner | F24: JIP | G24: BR | I24: FMIPA IPB | J24: Goverment | K24: Mrs. Ati | L24: +62 812-8974-499 | N24: Employee Gathering | O24: TB | P24: 20 | Q24: Neo Hotel Sentul | R24: =if(ISBLANK($T24),"",$T24-$S24+1) -> 1 | S24: 45689 | T24: 45689 | U24: =if(W24="","", S24-V24 & " days") -> 8 days | V24: 45681 | W24: P033 | X24: Cancel | Y24: Cancel | AA24: No Response | AB24: FALSE | AC24: FALSE | AD24: FALSE | AE24: FALSE | AF24: FALSE | AG24: FALSE | AI24: 9500000 | AR24: FALSE | AS24: FALSE
B25: 45666 | C25: LS | D25: Repeater | F25: JIP | G25: SB | I25: Telkom Property | J25: Corporate | K25: Mrs. Farha | L25: +62 813-1905-9828 | N25: Employee Gathering | O25: Production | Q25: Auditorium Telkom Landmark Tower | R25: =if(ISBLANK($T25),"",$T25-$S25+1) -> 2 | S25: 45691 | T25: 45692 | U25: =if(W25="","", S25-V25 & " days") -> 25 days | V25: 45666 | W25: P014 | X25: Signed & Deal | Y25: Confirm | AA25: - | AB25: TRUE | AC25: TRUE | AD25: TRUE | AE25: TRUE | AF25: FALSE | AG25: TRUE | AI25: 39150000 | AJ25: =AI25 -> 39150000 | AK25: Paid | AL25: Paid | AM25: Paid | AN25: Closed | AR25: FALSE | AS25: FALSE
B26: 45553 | C26: LS | D26: Repeater | F26: RA | G26: SB | I26: TK Nurul Huda CIbuluh | J26: Student | K26: Mrs TIni | L26: +62 857 1040 3573 | N26: Tour | O26: Study tour | P26: 91 | Q26: TSI | R26: =if(ISBLANK($T26),"",$T26-$S26+1) -> 1 | S26: 45693 | T26: 45693 | U26: =if(W26="","", S26-V26 & " days") -> 140 days | V26: 45553 | W26: P038 | X26: Signed & Deal | Y26: Confirm | AB26: TRUE | AC26: TRUE | AD26: TRUE | AE26: TRUE | AF26: FALSE | AG26: TRUE | AI26: 37100000 | AJ26: =AI26 -> 37100000 | AK26: Paid | AL26: Paid | AM26: Paid | AN26: Closed | AO26: https://drive.google.com/drive/folders/17EfwWcAsKZUR6-OaT86CtLuYMkg_Y3W2 | AQ26: https://www.instagram.com/onespiritasia/reel/DFwwnT6zJnt/ | AR26: TRUE | AS26: FALSE
B27: 45672 | C27: OS | D27: Hotel | E27: Ibu Beta | F27: JIP | G27: OME | I27: PT Asuransi Raksa Pratikara | J27: Corporate | K27: Mrs. Susy | L27: +62 816 976 101 | N27: Entertainment | O27: ENT | Q27: Royal Tulip Gunung Geulis | R27: =if(ISBLANK($T27),"",$T27-$S27+1) -> 1 | S27: 45694 | T27: 45694 | U27: =if(W27="","", S27-V27 & " days") -> 22 days | V27: 45672 | W27: P024 | X27: Signed & Deal | Y27: Confirm | AB27: TRUE | AC27: TRUE | AD27: TRUE | AE27: TRUE | AF27: FALSE | AG27: TRUE | AI27: 13000000 | AJ27: =AI27 -> 13000000 | AK27: Paid | AL27: Paid | AM27: Paid | AN27: Closed | AR27: FALSE | AS27: FALSE
B28: 45678 | C28: OS | D28: Repeater | F28: BR | G28: BR | I28: Daimler Truck - Soft SOP | J28: Corporate | K28: Mrs. Yessi | L28: +62 813-2717-0256 | N28: Production | O28: Production | Q28: Cikarang - Bekasi | R28: =if(ISBLANK($T28),"",$T28-$S28+1) -> 2 | S28: 45694 | T28: 45695 | U28: =if(W28="","", S28-V28 & " days") -> 16 days | V28: 45678 | W28: P032 | X28: Signed & Deal | Y28: Confirm | AB28: FALSE | AC28: FALSE | AD28: TRUE | AE28: TRUE | AF28: FALSE | AG28: TRUE | AI28: 51139176 | AJ28: =AI28 -> 51139176 | AK28: Paid | AL28: Paid | AM28: Paid | AN28: Closed | AR28: FALSE | AS28: FALSE
B29: 45663 | C29: OS | D29: Repeater | F29: MWB | G29: TF | I29: PT Sariling | J29: Corporate | K29: Mrs. Yunita Sitanggang | L29: +62 851-5777-8737 | N29: Employee Gathering | O29: TB | P29: 44 | Q29: Bogor/Bandung (TBC) | R29: =if(ISBLANK($T29),"",$T29-$S29+1) -> 2 | S29: 45695 | T29: 45696 | U29: =if(W29="","", S29-V29 & " days") -> 32 days | V29: 45663 | W29: P007 | X29: Cancel | Y29: Cancel | AA29: - | AB29: FALSE | AC29: FALSE | AD29: FALSE | AE29: TRUE | AF29: FALSE | AG29: FALSE | AI29: 75579900 | AR29: FALSE | AS29: FALSE
B30: 45668 | C30: OS | D30: Direct | F30: JIP | G30: SB | I30: Huawei | J30: Corporate | K30: Mrs. Resti | L30: +62 896-6199-6515 | N30: Employee Gathering | O30: Full Arrangement | P30: 93 | Q30: Royal Tulip Gunung Geulis | R30: =if(ISBLANK($T30),"",$T30-$S30+1) -> 2 | S30: 45695 | T30: 45696 | U30: =if(W30="","", S30-V30 & " days") -> 27 days | V30: 45668 | W30: P020 | X30: Cancel | Y30: Cancel | AA30: No Response | AB30: TRUE | AC30: FALSE | AD30: FALSE | AE30: FALSE | AF30: FALSE | AG30: FALSE | AI30: 426244995 | AR30: FALSE | AS30: FALSE
B31: 45660 | C31: OS | D31: Web | F31: UT | G31: UT | I31: PT Mega Waja Corporindo | J31: Corporate | K31: Mrs. Septi | N31: Employee Gathering | O31: Others | P31: 20 | Q31: Bogor | R31: =if(ISBLANK($T31),"",$T31-$S31+1) -> 2 | S31: 45696 | T31: 45697 | U31: =if(W31="","", S31-V31 & " days") -> 36 days | V31: 45660 | W31: P042 | X31: Cancel | Y31: Cancel | AB31: FALSE | AC31: FALSE | AD31: FALSE | AE31: FALSE | AF31: FALSE | AG31: FALSE | AI31: 36385800 | AR31: FALSE | AS31: FALSE
B32: 45672 | C32: OS | D32: Direct | F32: JIP | G32: BR | I32: BNI Jakarta | J32: Corporate | K32: Mrs. Risa | L32: +61 434 548 598 | N32: Employee Gathering | O32: TB - Scavenger Hunt | P32: 130 | Q32: Jogjakarta | R32: =if(ISBLANK($T32),"",$T32-$S32+1) -> 2 | S32: 45696 | T32: 45697 | U32: =if(W32="","", S32-V32 & " days") -> 24 days | V32: 45672 | W32: P030 | X32: Cancel | Y32: Cancel | AB32: TRUE | AC32: FALSE | AD32: FALSE | AE32: FALSE | AF32: FALSE | AG32: FALSE | AI32: 200069153 | AR32: FALSE | AS32: FALSE
B33: 45688 | C33: LS | D33: Direct | F33: BR | G33: BR | I33: RS Pertamina | J33: Corporate | K33: Mrs. Oche | L33: +62 818-0865-7356 | N33: Employee Gathering | O33: TB | P33: 60 | Q33: Bigland | R33: =if(ISBLANK($T33),"",$T33-$S33+1) -> 1 | S33: 45696 | T33: 45696 | U33: =if(W33="","", S33-V33 & " days") -> 7 days | V33: 45689 | W33: P043 | X33: Cancel | Y33: Cancel | AA33: Internal Reason | AB33: FALSE | AC33: FALSE | AD33: FALSE | AE33: FALSE | AF33: FALSE | AG33: FALSE | AI33: 9000000 | AR33: FALSE | AS33: FALSE
B34: 45681 | C34: OS | D34: Hotel | E34: Nanda | F34: JIP | G34: SB | I34: PLN IP UBP Kamojang (Batch 1) | J34: Goverment | K34: Mr Mishbah | L34: +62 822 3449 9535 | N34: Other | O34: Trekking | P34: 25 | Q34: Leuwi Asih | R34: =if(ISBLANK($T34),"",$T34-$S34+1) -> 1 | S34: 45699 | T34: 45699 | U34: =if(W34="","", S34-V34 & " days") -> 18 days | V34: 45681 | W34: P039 | X34: Signed & Deal | Y34: Confirm | Z34: https://drive.google.com/file/d/1jp6i0BvqlQfrwQcJBuGIF2oTErSZgcfa/view?usp=drive_link | AB34: TRUE | AC34: TRUE | AD34: TRUE | AE34: TRUE | AF34: FALSE | AG34: TRUE | AI34: 14957250 | AJ34: =AI34 -> 14957250 | AK34: Paid | AL34: Paid | AM34: Paid | AN34: Closed | AO34: https://drive.google.com/drive/folders/1zMDuPh1E2kf6Yd4UtQruXN9u1f390I37?usp=sharing | AR34: TRUE | AS34: FALSE | AT34: Payment LS 14 Days
B35: 45666 | C35: OS | D35: Repeater | F35: JIP | G35: TF | I35: PT Sinergi Wahana Gemilang | J35: Corporate | K35: Mrs. Tiwi | L35: +62 812-8059-2908 | N35: Employee Gathering | O35: Full Arrangement | P35: 120 | Q35: Hotel Santika Kuningan | R35: =if(ISBLANK($T35),"",$T35-$S35+1) -> 2 | S35: 45700 | T35: 45701 | U35: =if(W35="","", S35-V35 & " days") -> 34 days | V35: 45666 | W35: P016 | X35: Signed & Deal | Y35: Confirm | AA35: - | AB35: TRUE | AC35: TRUE | AD35: TRUE | AE35: TRUE | AF35: FALSE | AG35: TRUE | AI35: 25000000 | AJ35: =AI35 -> 25000000 | AK35: Paid | AL35: Paid | AM35: Paid | AN35: Closed | AO35: https://drive.google.com/drive/folders/1BEyJ6Huic6QO3Sz4pVyOBL0y2yCqDv26?usp=sharing | AQ35: https://www.instagram.com/onespiritasia/reel/DGKVoHozZvI/ | AR35: TRUE | AS35: FALSE
B36: 45672 | C36: OS | D36: Hotel | F36: JIP | G36: OME | I36: PT. MC Urban Development Indonesia | J36: Corporate | K36: Mr. Dana Dwi Satria | L36: +62 811 1933 0168 | N36: Employee Gathering | O36: Others | P36: 20 | Q36: Pullman Ciawi | R36: =if(ISBLANK($T36),"",$T36-$S36+1) -> 1 | S36: 45701 | T36: 45701 | U36: =if(W36="","", S36-V36 & " days") -> 29 days | V36: 45672 | W36: P022 | X36: Cancel | Y36: Cancel | AB36: TRUE | AC36: FALSE | AD36: FALSE | AE36: FALSE | AF36: FALSE | AG36: FALSE | AI36: 8000000 | AR36: FALSE | AS36: FALSE
B37: 45681 | C37: OS | D37: Hotel | E37: Nanda | F37: JIP | G37: SB | I37: PLN IP UBP Kamojang ( Batch 2 ) | J37: Goverment | K37: Mr Mishbah | L37: +62 822 3449 9535 | N37: Other | O37: Trekking | P37: 25 | Q37: Leusi Asih | R37: =if(ISBLANK($T37),"",$T37-$S37+1) -> 1 | S37: 45701 | T37: 45701 | U37: =if(W37="","", S37-V37 & " days") -> 20 days | V37: 45681 | W37: P040 | X37: Signed & Deal | Y37: Confirm | Z37: https://drive.google.com/file/d/1PKONQAygQGPxJjNNJEs-p5jYnn4zWhj8/view?usp=drive_link | AB37: TRUE | AC37: TRUE | AD37: TRUE | AE37: TRUE | AF37: FALSE | AG37: TRUE | AI37: 14529900 | AJ37: =AI37 -> 14529900 | AK37: Paid | AL37: Paid | AM37: Paid | AN37: Closed | AO37: https://drive.google.com/drive/folders/1FmBuxbny6KG7Z8QfaFhOUs1t4xwnDMs2?usp=sharing | AR37: TRUE | AS37: FALSE | AT37: Payment LS 14 Days
B38: 45567 | C38: OS | D38: Hotel | F38: JIP | G38: OME | I38: Dharma Wanita BNI Pusat | J38: Corporate | K38: Mrs. Denis | L38: +62 812 8130 412 | N38: Employee Gathering | O38: Others | P38: 120 | Q38: Royal Tulip Gunung Geulis | R38: =if(ISBLANK($T38),"",$T38-$S38+1) -> 1 | S38: 45702 | T38: 45702 | U38: =if(W38="","", S38-V38 & " days") -> 135 days | V38: 45567 | W38: P050 | X38: Cancel | Y38: Cancel | AB38: FALSE | AC38: FALSE | AD38: FALSE | AE38: FALSE | AF38: FALSE | AG38: FALSE | AI38: 97680000 | AR38: FALSE | AS38: FALSE
B39: 45699 | C39: OS | D39: Hotel | F39: JIP | G39: TF | I39: ANTAM | J39: Corporate | K39: Mrs. Wirda | N39: Production | O39: Production | R39: =if(ISBLANK($T39),"",$T39-$S39+1) -> 1 | S39: 45702 | T39: 45702 | U39: =if(W39="","", S39-V39 & " days") -> 3 days | V39: 45699 | W39: P053 | X39: Cancel | Y39: Cancel | AB39: TRUE | AC39: FALSE | AD39: FALSE | AE39: FALSE | AF39: FALSE | AG39: FALSE | AI39: 7104000 | AR39: FALSE | AS39: FALSE
B40: 45665 | C40: OS | D40: Hotel | E40: Puji | F40: JIP | G40: SB | I40: Krakatau Steel | J40: Corporate | K40: Mrs. Dyosferra | L40: +62 877-7431-1499 | N40: Employee Gathering | O40: Production | P40: 30 | Q40: Pesona Alam Resort & Spa | R40: =if(ISBLANK($T40),"",$T40-$S40+1) -> 2 | S40: 45705 | T40: 45706 | U40: =if(W40="","", S40-V40 & " days") -> 40 days | V40: 45665 | W40: P018 | X40: Signed & Deal | Y40: Confirm | AA40: - | AB40: TRUE | AC40: TRUE | AD40: TRUE | AE40: TRUE | AF40: FALSE | AG40: TRUE | AI40: 58000000 | AJ40: =AI40 -> 58000000 | AK40: Paid | AL40: Paid | AM40: Paid | AN40: Closed | AO40: https://drive.google.com/drive/folders/1Y-fvzu1KSj7KptbYLn_7nvDXom35_Wt_?usp=sharing | AQ40: https://www.instagram.com/onespiritasia/reel/DF444cATBiX/ | AR40: TRUE | AS40: FALSE
B41: 45683 | C41: OS | D41: Hotel | F41: JIP | G41: TF | I41: Trakindo | J41: Corporate | K41: Ardi Sobby | L41: 62 811-8010-2950 | N41: Meeting | O41: Production | P41: 50 | Q41: Aston Sentul | R41: =if(ISBLANK($T41),"",$T41-$S41+1) -> 3 | S41: 45705 | T41: 45707 | U41: =if(W41="","", S41-V41 & " days") -> 22 days | V41: 45683 | W41: P036 | X41: Cancel | Y41: Cancel | AB41: TRUE | AC41: FALSE | AD41: FALSE | AE41: FALSE | AF41: FALSE | AG41: FALSE | AI41: Rp296,641,950 | AR41: FALSE | AS41: FALSE
...

Sheet Helper
A1: Employee List | E1: Inquiry By | F1: Category Company | G1: Event Category | H1: Program
E2: Hotel | F2: Corporate | G2: Employee Gathering | H2: TB | J2: INQ By | K2: SUM of Budget (Rp) | M2: INQ By | N2: SUM of Budget (Rp) | P2: Event Date Start | Q2: COUNTA of Quotation Number | T2: Event Date End | U2: COUNTA of Quotation Number | W2: PO | X2: SUM of Budget (Rp) | AA2: Target Revenue 2025
E3: Repeater | F3: Goverment | G3: Family Gathering | H3: TB - Scavenger Hunt | J3: Direct | K3: 9899900392 | M3: Direct | N3: 9899900392 | P3: June-2025 | Q3: 1 | R3: {=XLOOKUP(P3,Workflow!$S$6:$S$270,Workflow!$W$6:$W$270)} -> P073 | T3: June-2025 | U3: 1 | V3: {=XLOOKUP(T3,Workflow!$T$6:$T$270,Workflow!$W$6:$W$270)} -> P073 | W3: AR | X3: 1538726557 | Y3: =K81/X3*100% -> 0.80684707 | AA3: Target 2025 | AB3: SUM of Target
E4: Partner | F4: Student | G4: Production | H4: FG | J4: Hotel | K4: 10976511799 | M4: Hotel | N4: 10976511799 | P4: 46067 | Q4: 1 | R4: {=XLOOKUP(P4,Workflow!$S$6:$S$270,Workflow!$W$6:$W$270)} -> P175 | T4: 46067 | U4: 1 | V4: {=XLOOKUP(T4,Workflow!$T$6:$T$270,Workflow!$W$6:$W$270)} -> P175 | W4: BR | X4: 5990341692 | Y4: =K82/X4*100% -> 0.16798411 | AA4: Mohammad Ramli | AB4: 3000000000
A5: Employee ID | B5: Employee Name | C5: Contact | E5: Direct | F5: Other | G5: Entertainment | H5: OFR | J5: Instagram | K5: 1562303761 | M5: Instagram | N5: 1562303761 | P5: 46042 | Q5: 1 | R5: {=XLOOKUP(P5,Workflow!$S$6:$S$270,Workflow!$W$6:$W$270)} -> P221 | T5: 46042 | U5: 1 | V5: {=XLOOKUP(T5,Workflow!$T$6:$T$270,Workflow!$W$6:$W$270)} -> P221 | W5: JC | X5: 226594000 | Y5: =K83/X5*100% -> 1 | AA5: Jaka Iklas Pratama | AB5: 3000000000
A6: 1001 | B6: JC | C6: +62 896 0113 1400 | E6: Instagram | F6: Campus | G6: Tour | H6: PB | J6: Partner | K6: 2698687930 | L6: =AVERAGE(K3:K8) -> 5252603314 | M6: Partner | N6: 2698687930 | P6: 46023 | Q6: 1 | R6: {=XLOOKUP(P6,Workflow!$S$6:$S$270,Workflow!$W$6:$W$270)} -> P244 | T6: 46023 | U6: 1 | V6: {=XLOOKUP(T6,Workflow!$T$6:$T$270,Workflow!$W$6:$W$270)} -> P244 | W6: JIP | X6: 15300327586 | Y6: =K84/X6*100% -> 0.40939534 | AA6: Ridho Abdullah | AB6: 2000000000
A7: 1002 | B7: MWB | C7: +62 821 1299 7371 | E7: Web | G7: Meeting | H7: RFT | J7: Repeater | K7: 6246172201 | M7: Repeater | N7: 6246172201 | P7: 46017 | Q7: 1 | R7: {=XLOOKUP(P7,Workflow!$S$6:$S$270,Workflow!$W$6:$W$270)} -> P247 | T7: 46019 | U7: 1 | V7: {=XLOOKUP(T7,Workflow!$T$6:$T$270,Workflow!$W$6:$W$270)} -> P247 | W7: MWB | X7: 1028064900 | Y7: =K85/X7*100% -> 0.051052224 | AA7: Syarah Syukrilah | AB7: 1000000000
A8: 1003 | B8: JIP | C8: +62 858 8882 8443 | E8: Other | G8: Other | H8: ARC | J8: Web | K8: 132043800 | M8: Web | N8: 132043800 | P8: 46014 | Q8: 1 | R8: {=XLOOKUP(P8,Workflow!$S$6:$S$270,Workflow!$W$6:$W$270)} -> P248 | T8: 46015 | U8: 1 | V8: {=XLOOKUP(T8,Workflow!$T$6:$T$270,Workflow!$W$6:$W$270)} -> P248 | W8: RA | X8: 37100000 | Y8: =K86/X8*100% -> 1 | AA8: Light Spirit | AB8: 1000000000
A9: 1004 | B9: DS | C9: +62 858 9020 6621 | G9: Sport Event | H9: Production | J9: Grand Total | K9: 31515619883 | M9: Grand Total | N9: 31515619883 | P9: 46013 | Q9: 1 | R9: {=XLOOKUP(P9,Workflow!$S$6:$S$270,Workflow!$W$6:$W$270)} -> P258 | T9: 46014 | U9: 1 | V9: {=XLOOKUP(T9,Workflow!$T$6:$T$270,Workflow!$W$6:$W$270)} -> P258 | W9: SBK | X9: 839618080 | Y9: =K87/X9*100% -> 0.84943309 | AA9: Arin Fitria | AB9: 800000000
A10: 1005 | B10: RA | C10: +62 811 1103 389 | H10: Tour | P10: 46010 | Q10: 2 | R10: {=XLOOKUP(P10,Workflow!$S$6:$S$270,Workflow!$W$6:$W$270)} -> P253 | T10: 46010 | U10: 2 | V10: {=XLOOKUP(T10,Workflow!$T$6:$T$270,Workflow!$W$6:$W$270)} -> P253 | W10: SR | X10: 1052502111 | Y10: =K88/X10*100% -> 0.60806269 | AA10: Taufan Hidayat | AB10: 500000000
A11: 1006 | B11: BR | C11: +62 857 8031 3089 | H11: ENT | J11: Program Status | K11: COUNTA of Quotation Number | P11: 46009 | Q11: 1 | R11: {=XLOOKUP(P11,Workflow!$S$6:$S$270,Workflow!$W$6:$W$270)} -> P245 | T11: 46009 | U11: 1 | V11: {=XLOOKUP(T11,Workflow!$T$6:$T$270,Workflow!$W$6:$W$270)} -> P245 | W11: SYS | X11: 4828612312 | Y11: =K89/X11*100% -> 0.025408878 | AA11: Putera Katresna | AB11: 500000000
A12: 1007 | B12: AR | C12: +62 858 1437 1788 | J12: Cancel | K12: 142 | P12: 46006 | Q12: 1 | R12: {=XLOOKUP(P12,Workflow!$S$6:$S$270,Workflow!$W$6:$W$270)} -> P256 | T12: 46006 | U12: 1 | V12: {=XLOOKUP(T12,Workflow!$T$6:$T$270,Workflow!$W$6:$W$270)} -> P256 | W12: TF | X12: 472622845 | Y12: =K90/X12*100% -> 0.57078473 | AA12: M.Syahrul Ramadhan | AB12: 200000000
A13: 1008 | B13: SYS | C13: +62 812 9730 9703 | J13: Confirm | K13: 122 | M13: PO | N13: COUNTA of Quotation Number | P13: 46004 | Q13: 1 | R13: {=XLOOKUP(P13,Workflow!$S$6:$S$270,Workflow!$W$6:$W$270)} -> P254 | T13: 46005 | U13: 1 | V13: {=XLOOKUP(T13,Workflow!$T$6:$T$270,Workflow!$W$6:$W$270)} -> P242 | W13: UT | X13: 201109800 | Y13: =0/X13*100% -> 0
A14: 1009 | B14: TF | C14: +62 896 5180 7061 | J14: Grand Total | K14: 264 | M14: AR | N14: 5 | P14: 46003 | Q14: 5 | R14: {=XLOOKUP(P14,Workflow!$S$6:$S$270,Workflow!$W$6:$W$270)} -> P230 | T14: 46004 | U14: 2 | V14: {=XLOOKUP(T14,Workflow!$T$6:$T$270,Workflow!$W$6:$W$270)} -> P249 | W14: Grand Total | X14: 31515619883 | Y14: =0/X14*100% -> 0
A15: 1010 | B15: SR | C15: +62 857 7407 3054 | M15: BR | N15: 31 | P15: 46002 | Q15: 1 | R15: {=XLOOKUP(P15,Workflow!$S$6:$S$270,Workflow!$W$6:$W$270)} -> P249 | T15: 46003 | U15: 3 | V15: {=XLOOKUP(T15,Workflow!$T$6:$T$270,Workflow!$W$6:$W$270)} -> P230
A16: 1011 | B16: UT | C16: +62 821 1191 0614 | M16: JC | N16: 1 | P16: 46000 | Q16: 1 | R16: {=XLOOKUP(P16,Workflow!$S$6:$S$270,Workflow!$W$6:$W$270)} -> P255 | T16: 46001 | U16: 1 | V16: {=XLOOKUP(T16,Workflow!$T$6:$T$270,Workflow!$W$6:$W$270)} -> P234
A17: 1012 | B17: SBK | C17: +62 812 9749 9543 | M17: JIP | N17: 181 | P17: 45999 | Q17: 2 | R17: {=XLOOKUP(P17,Workflow!$S$6:$S$270,Workflow!$W$6:$W$270)} -> P224 | T17: 46000 | U17: 1 | V17: {=XLOOKUP(T17,Workflow!$T$6:$T$270,Workflow!$W$6:$W$270)} -> P255
A18: 1013 | B18: OME | C18: +62 822 4961 6181 | M18: MWB | N18: 3 | P18: 45996 | Q18: 3 | R18: {=XLOOKUP(P18,Workflow!$S$6:$S$270,Workflow!$W$6:$W$270)} -> P219 | T18: 45999 | U18: 1 | V18: {=XLOOKUP(T18,Workflow!$T$6:$T$270,Workflow!$W$6:$W$270)} -> P224
M19: RA | N19: 1 | P19: 45994 | Q19: 2 | R19: {=XLOOKUP(P19,Workflow!$S$6:$S$270,Workflow!$W$6:$W$270)} -> P176 | T19: 45996 | U19: 3 | V19: {=XLOOKUP(T19,Workflow!$T$6:$T$270,Workflow!$W$6:$W$270)} -> P219 | Y19: =K81/X19*100% -> 1.5518963
E20: =L70/L71*100% -> 0.3355004 | M20: SBK | N20: 11 | P20: 45992 | Q20: 2 | R20: {=XLOOKUP(P20,Workflow!$S$6:$S$270,Workflow!$W$6:$W$270)} -> P204 | T20: 45995 | U20: 1 | V20: {=XLOOKUP(T20,Workflow!$T$6:$T$270,Workflow!$W$6:$W$270)} -> P176 | Y20: =K84/X20*100% -> 2.0879609
E21: =K46/K47*100% -> 0.46212121 | M21: SR | N21: 5 | P21: 45990 | Q21: 2 | R21: {=XLOOKUP(P21,Workflow!$S$6:$S$270,Workflow!$W$6:$W$270)} -> P220 | T21: 45994 | U21: 1 | V21: {=XLOOKUP(T21,Workflow!$T$6:$T$270,Workflow!$W$6:$W$270)} -> P251 | Y21: =K87/X21*100% -> 0.71319938
M22: SYS | N22: 19 | P22: 45989 | Q22: 3 | R22: {=XLOOKUP(P22,Workflow!$S$6:$S$270,Workflow!$W$6:$W$270)} -> P215 | T22: 45993 | U22: 1 | V22: {=XLOOKUP(T22,Workflow!$T$6:$T$270,Workflow!$W$6:$W$270)} -> P246 | Y22: =K88/X22*100% -> 3.1999363
J23: Payment Status | K23: COUNTA of Quotation Number | M23: TF | N23: 3 | P23: 45988 | Q23: 2 | R23: {=XLOOKUP(P23,Workflow!$S$6:$S$270,Workflow!$W$6:$W$270)} -> P134 | T23: 45992 | U23: 1 | V23: {=XLOOKUP(T23,Workflow!$T$6:$T$270,Workflow!$W$6:$W$270)} -> P204 | Y23: =K82/X23*100% -> 0.33542741
J24: Invoice Sent | K24: 1 | M24: UT | N24: 4 | P24: 45987 | Q24: 1 | R24: {=XLOOKUP(P24,Workflow!$S$6:$S$270,Workflow!$W$6:$W$270)} -> P259 | T24: 45991 | U24: 3 | V24: {=XLOOKUP(T24,Workflow!$T$6:$T$270,Workflow!$W$6:$W$270)} -> P215 | Y24: =0/X24*100% -> 0
J25: Out Standing | K25: 12 | M25: Grand Total | N25: 264 | P25: 45986 | Q25: 1 | R25: {=XLOOKUP(P25,Workflow!$S$6:$S$270,Workflow!$W$6:$W$270)} -> P127 | T25: 45990 | U25: 1 | V25: {=XLOOKUP(T25,Workflow!$T$6:$T$270,Workflow!$W$6:$W$270)} -> P220 | Y25: =K86/X25*100% -> 0.01855
J26: Paid | K26: 103 | P26: 45983 | Q26: 3 | R26: {=XLOOKUP(P26,Workflow!$S$6:$S$270,Workflow!$W$6:$W$270)} -> P212 | T26: 45989 | U26: 1 | V26: {=XLOOKUP(T26,Workflow!$T$6:$T$270,Workflow!$W$6:$W$270)} -> P239 | Y26: =K89/X26*100% -> 0.12268962
J27: Grand Total | K27: 116 | M27: Cancel Reason | N27: COUNTA of Quotation Number | P27: 45982 | Q27: 5 | R27: {=XLOOKUP(P27,Workflow!$S$6:$S$270,Workflow!$W$6:$W$270)} -> P185 | T27: 45988 | U27: 2 | V27: {=XLOOKUP(T27,Workflow!$T$6:$T$270,Workflow!$W$6:$W$270)} -> P134 | Y27: =K90/X27*100% -> 0.53953181
N28: 181 | P28: 45980 | Q28: 1 | R28: {=XLOOKUP(P28,Workflow!$S$6:$S$270,Workflow!$W$6:$W$270)} -> P207 | T28: 45987 | U28: 1 | V28: {=XLOOKUP(T28,Workflow!$T$6:$T$270,Workflow!$W$6:$W$270)} -> P259 | Y28: =K89/X28*100% -> 0.010224135
M29: - | N29: 37 | P29: 45975 | Q29: 2 | R29: {=XLOOKUP(P29,Workflow!$S$6:$S$270,Workflow!$W$6:$W$270)} -> P227 | T29: 45986 | U29: 1 | V29: {=XLOOKUP(T29,Workflow!$T$6:$T$270,Workflow!$W$6:$W$270)} -> P127
M30: Budget | N30: 5 | P30: 45974 | Q30: 1 | R30: {=XLOOKUP(P30,Workflow!$S$6:$S$270,Workflow!$W$6:$W$270)} -> P180 | T30: 45983 | U30: 3 | V30: {=XLOOKUP(T30,Workflow!$T$6:$T$270,Workflow!$W$6:$W$270)} -> P212
J31: PM | K31: Task ID | M31: Competitor | N31: 12 | P31: 45972 | Q31: 1 | R31: {=XLOOKUP(P31,Workflow!$S$6:$S$270,Workflow!$W$6:$W$270)} -> P237 | T31: 45982 | U31: 6 | V31: {=XLOOKUP(T31,Workflow!$T$6:$T$270,Workflow!$W$6:$W$270)} -> P207
J32: AR | K32: 1 | M32: Internal Reason | N32: 9 | P32: 45969 | Q32: 2 | R32: {=XLOOKUP(P32,Workflow!$S$6:$S$270,Workflow!$W$6:$W$270)} -> P178 | T32: 45976 | U32: 1 | V32: {=XLOOKUP(T32,Workflow!$T$6:$T$270,Workflow!$W$6:$W$270)} -> P236
J33: BR | K33: 66 | M33: No Response | N33: 18 | P33: 45967 | Q33: 1 | R33: {=XLOOKUP(P33,Workflow!$S$6:$S$270,Workflow!$W$6:$W$270)} -> P210 | T33: 45975 | U33: 1 | V33: {=XLOOKUP(T33,Workflow!$T$6:$T$270,Workflow!$W$6:$W$270)} -> P227
J34: MDL | K34: 1 | M34: Postponed | N34: 2 | P34: 45962 | Q34: 2 | R34: {=XLOOKUP(P34,Workflow!$S$6:$S$270,Workflow!$W$6:$W$270)} -> P208 | T34: 45974 | U34: 1 | V34: {=XLOOKUP(T34,Workflow!$T$6:$T$270,Workflow!$W$6:$W$270)} -> P180
J35: MWB | K35: 17 | M35: Grand Total | N35: 264 | P35: 45961 | Q35: 3 | R35: {=XLOOKUP(P35,Workflow!$S$6:$S$270,Workflow!$W$6:$W$270)} -> P147 | T35: 45973 | U35: 2 | V35: {=XLOOKUP(T35,Workflow!$T$6:$T$270,Workflow!$W$6:$W$270)} -> P237
J36: OME | K36: 50 | P36: 45960 | Q36: 1 | R36: {=XLOOKUP(P36,Workflow!$S$6:$S$270,Workflow!$W$6:$W$270)} -> P196 | T36: 45970 | U36: 1 | V36: {=XLOOKUP(T36,Workflow!$T$6:$T$270,Workflow!$W$6:$W$270)} -> P178
J37: RA | K37: 1 | P37: 45957 | Q37: 1 | R37: {=XLOOKUP(P37,Workflow!$S$6:$S$270,Workflow!$W$6:$W$270)} -> P217 | T37: 45969 | U37: 1 | V37: {=XLOOKUP(T37,Workflow!$T$6:$T$270,Workflow!$W$6:$W$270)} -> P198
J38: SB | K38: 45 | M38: Customer Category | N38: COUNTA of Quotation Number | P38: 45955 | Q38: 1 | R38: {=XLOOKUP(P38,Workflow!$S$6:$S$270,Workflow!$W$6:$W$270)} -> P229 | T38: 45967 | U38: 1 | V38: {=XLOOKUP(T38,Workflow!$T$6:$T$270,Workflow!$W$6:$W$270)} -> P210
J39: SYS | K39: 12 | N39: 2 | P39: 45954 | Q39: 3 | R39: {=XLOOKUP(P39,Workflow!$S$6:$S$270,Workflow!$W$6:$W$270)} -> P106 | T39: 45963 | U39: 1 | V39: {=XLOOKUP(T39,Workflow!$T$6:$T$270,Workflow!$W$6:$W$270)} -> P226
J40: TF | K40: 44 | M40: Campus | N40: 4 | P40: 45953 | Q40: 1 | R40: {=XLOOKUP(P40,Workflow!$S$6:$S$270,Workflow!$W$6:$W$270)} -> P223 | T40: 45962 | U40: 3 | V40: {=XLOOKUP(T40,Workflow!$T$6:$T$270,Workflow!$W$6:$W$270)} -> P196
...
